<?xml version="1.0" encoding="utf-8"?>
<!-- =================================================================================== -->
<!-- |    This document was autogenerated by xacro from rbvogui_xl_lift_ur10e.urdf.xacro | -->
<!-- |    EDITING THIS FILE BY HAND IS NOT RECOMMENDED                                 | -->
<!-- =================================================================================== -->
<!-- RBVogui XL -->
<robot name="rbvogui">
  <!-- ***************** -->
  <!-- Imported elements -->
  <!-- ***************** -->
  <!-- First we import all posible elements defined in the urdf.xacro files. All these elements are defined as macro:xacros -->
  <!-- Source: https://en.wikipedia.org/wiki/List_of_moments_of_inertia-->
  <!-- in kg-->
  <!-- - - - - - - - - - - - - - EWELLIX LIFT - - - - - - - - - - - - - -->
  <!-- Source: https://en.wikipedia.org/wiki/List_of_moments_of_inertia-->
  <!-- Source: https://en.wikipedia.org/wiki/List_of_moments_of_inertia-->
  <!-- source en.wikipedia.org/wiki/List_of_moments_of_inertia-->
  <!-- This file unifies all sensors that can be used on simulation, defined as xacro:macros -->
  <!-- Includes -->
  <gazebo>
    <plugin filename="libgazebo_ros_control.so" name="ros_control">
      <!--<robotNamespace>/summit_xl</robotNamespace>-->
      <robotParam>robot_description</robotParam>
      <controlPeriod>0.001</controlPeriod>
      <robotSimType>gazebo_ros_control/DefaultRobotHWSim</robotSimType>
      <legacyModeNS>true</legacyModeNS>
    </plugin>
  </gazebo>
  <!-- *************** -->
  <!-- Robots Elements -->
  <!-- *************** -->
  <!-- Here we create the robot elements using the xacro:macros imported at the beggining of this file -->
  <link name="robot_base_footprint">
    <visual>
      <origin rpy="0 0 0" xyz="0 0 0"/>
      <geometry>
        <box size="0.001 0.001 0.001"/>
      </geometry>
    </visual>
  </link>
  <joint name="robot_base_footprint_joint" type="fixed">
    <origin rpy="0 0 0" xyz="0 0 0.1425"/>
    <!-- ${wheel_radius} property must be defined inside wheel description -->
    <parent link="robot_base_footprint"/>
    <child link="robot_base_link"/>
  </joint>
  <!-- BASE_LINK -->
  <link name="robot_base_link"/>
  <!-- Chassis -->
  <joint name="robot_chassis_joint" type="fixed">
    <origin rpy="0 0 0" xyz="0 0 0.23376"/>
    <parent link="robot_base_link"/>
    <child link="robot_chassis_link"/>
  </joint>
  <!-- Chassis -->
  <link name="robot_chassis_link">
    <inertial>
      <mass value="25.0"/>
      <origin xyz="0 0 0.376"/>
      <inertia ixx="1.82410208333" ixy="0" ixz="0" iyy="3.78427083333" iyz="0" izz="4.70743541667"/>
    </inertial>
    <visual>
      <origin rpy="0 0 0" xyz="0 0 0"/>
      <geometry>
        <mesh filename="package://rbvogui_description/rbvogui_xl_chassis.stl"/>
      </geometry>
      <material name="darkgrey">
        <color rgba="0.1 0.1 0.1 1"/>
      </material>
    </visual>
    <collision>
      <origin rpy="0 0 0 " xyz="0 0 0"/>
      <geometry>
        <mesh filename="package://rbvogui_description/rbvogui_xl_chassis.stl"/>
      </geometry>
    </collision>
  </link>
  <!-- Battery -->
  <joint name="robot_battery_joint" type="fixed">
    <origin rpy="0 0 0 " xyz="0 0 0"/>
    <parent link="robot_chassis_link"/>
    <child link="robot_battery_link"/>
  </joint>
  <!-- Battery -->
  <link name="robot_battery_link">
    <inertial>
      <mass value="20.0"/>
      <origin xyz="0 0 0"/>
      <inertia ixx="1.0" ixy="0.0" ixz="0.0" iyy="1.0" iyz="0.0" izz="1.0"/>
    </inertial>
    <visual>
      <origin rpy="0 0 0" xyz="0 0 0"/>
      <geometry>
        <mesh filename="package://rbvogui_description/rbvogui_xl_battery.stl"/>
      </geometry>
      <material name="darkgrey">
        <color rgba="0.1 0.1 0.1 1"/>
      </material>
    </visual>
    <collision>
      <origin rpy="0 0 0 " xyz="0 0 0"/>
      <geometry>
        <mesh filename="package://rbvogui_description/rbvogui_xl_battery.stl"/>
      </geometry>
    </collision>
  </link>
  <!-- Contactors -->
  <joint name="robot_contactors_joint" type="fixed">
    <origin rpy="0 0 0 " xyz="0.6405 0 0.10264"/>
    <parent link="robot_chassis_link"/>
    <child link="robot_contactors_link"/>
  </joint>
  <!-- Contactors -->
  <link name="robot_contactors_link">
    <visual>
      <origin rpy="0 0 0" xyz="0 0 0"/>
      <geometry>
        <mesh filename="package://rbvogui_description/rbvogui_contactors.stl"/>
      </geometry>
      <material name="lighbrown">
        <color rgba="0.7 0.3 0.0 1"/>
      </material>
    </visual>
  </link>
  <!-- Logos -->
  <joint name="robot_base_logos_joint" type="fixed">
    <origin rpy="0 0 0 " xyz="0 0 -0.08376"/>
    <parent link="robot_chassis_link"/>
    <child link="robot_base_logos_link"/>
  </joint>
  <!-- Logos -->
  <link name="robot_base_logos_link">
    <visual>
      <origin rpy="0 0 0" xyz="0 0 -0.06"/>
      <geometry>
        <mesh filename="package://rbvogui_description/rbvogui_logos.stl" scale="1.24 1.24 1"/>
      </geometry>
      <material name="lightred">
        <color rgba="0.9 0.2 0.2 1"/>
      </material>
    </visual>
  </link>
  <joint name="robot_leds_joint" type="fixed">
    <origin rpy="0 0 0 " xyz="0 0 0.12624"/>
    <parent link="robot_chassis_link"/>
    <child link="robot_leds_link"/>
  </joint>
  <link name="robot_leds_link">
    <visual>
      <origin rpy="0 0 0.0" xyz="0 0 0"/>
      <geometry>
        <mesh filename="package://rbvogui_description/rbvogui_xl_leds.stl"/>
      </geometry>
      <material name="lightgreen">
        <color rgba="0.1 1.0 0.1 1"/>
      </material>
    </visual>
  </link>
  <gazebo reference="robot_base_link">
    <visual>
      <material>
        <ambient>0.0 0.0 0.0 1.0</ambient>
        <diffuse>0.2 0.2 0.2 1.0</diffuse>
        <specular>0.508273 0.508273 0.508273 1.0</specular>
        <emissive>0.0 0.0 0.0 0.0</emissive>
      </material>
    </visual>
  </gazebo>
  <gazebo reference="robot_chassis_link">
    <visual>
      <material>
        <ambient>0.0 0.0 0.0 1.0</ambient>
        <diffuse>0.2 0.2 0.2 1.0</diffuse>
        <specular>0.508273 0.508273 0.508273 1.0</specular>
        <emissive>0.0 0.0 0.0 0.0</emissive>
      </material>
    </visual>
  </gazebo>
  <gazebo reference="robot_battery_link">
    <visual>
      <material>
        <ambient>0.0 0.0 0.0 1.0</ambient>
        <diffuse>0.2 0.2 0.2 1.0</diffuse>
        <specular>0.508273 0.508273 0.508273 1.0</specular>
        <emissive>0.0 0.0 0.0 0.0</emissive>
      </material>
    </visual>
  </gazebo>
  <gazebo reference="robot_contactors_link">
    <visual>
      <material>
        <ambient>0.7 0.3 0.0 1.0</ambient>
        <diffuse>0.7 0.3 0.0 1.0</diffuse>
        <specular>0.7 0.3 0.0 1.0</specular>
        <emissive>0.0 0.0 0.0 0.0</emissive>
      </material>
    </visual>
  </gazebo>
  <gazebo reference="robot_base_logos_link">
    <visual>
      <material>
        <ambient>1.0 0.0 0.0 1.0</ambient>
        <diffuse>0.50754 0.50754 0.50754 1.0</diffuse>
        <specular>0.508273 0.508273 0.508273 1.0</specular>
        <emissive>0.0 0.0 0.0 0.0</emissive>
      </material>
    </visual>
  </gazebo>
  <gazebo reference="robot_leds_link">
    <visual>
      <material>
        <ambient>0.0 1.0 0.0 1.0</ambient>
        <diffuse>0.0 1.0 0.0 1.0</diffuse>
        <specular>0.0 1.0 0.0 1.0</specular>
        <emissive>0.0 0.0 0.0 0.0</emissive>
      </material>
    </visual>
  </gazebo>
  <!--MOTOR WHEEL -->
  <joint name="robot_front_right_motor_wheel_joint" type="revolute">
    <parent link="robot_base_link"/>
    <child link="robot_front_right_motor_wheel"/>
    <origin rpy="0 0 0" xyz="0.4795 -0.2925 0.0"/>
    <axis rpy="0 0 0" xyz="0 0 1"/>
    <!-- limit effort="${steer_joint_effort_limit}" velocity="${steer_joint_velocity_limit}" lower="-1.5708" upper="1.5708" / -->
    <limit effort="100.0" lower="-3.00" upper="3.00" velocity="2.83"/>
    <joint_properties damping="2.0" friction="1.0"/>
  </joint>
  <transmission name="robot_front_right_motor_wheel_trans">
    <type>transmission_interface/SimpleTransmission</type>
    <joint name="robot_front_right_motor_wheel_joint">
      <hardwareInterface>hardware_interface/PositionJointInterface</hardwareInterface>
    </joint>
    <actuator name="robot_front_right_motor_wheel_motor">
      <hardwareInterface>hardware_interface/PositionActuatorInterface</hardwareInterface>
      <mechanicalReduction>1.0</mechanicalReduction>
    </actuator>
  </transmission>
  <link name="robot_front_right_motor_wheel">
    <visual>
      <origin rpy="0 0 3.14159265359" xyz="0 0 0"/>
      <geometry>
        <mesh filename="package://rbvogui_description/hub_rbvogui_xl.stl"/>
      </geometry>
      <material name="red">
        <color rgba="0.9 0.1 0.1 1"/>
      </material>
    </visual>
    <collision>
      <origin rpy="0 0 3.14159265359" xyz="0 0 0"/>
      <geometry>
        <mesh filename="package://rbvogui_description/hub_rbvogui_xl.stl"/>
      </geometry>
    </collision>
    <inertial>
      <mass value="4"/>
      <origin rpy="0 0 3.14159265359" xyz="0 0 0.12"/>
      <inertia ixx="0.0335494791667" ixy="0" ixz="0" iyy="0.0335494791667" iyz="0" izz="0.050765625"/>
    </inertial>
  </link>
  <gazebo reference="robot_front_right_motor_wheel">
    <visual>
      <material>
        <ambient>1.0 0.0 0.0 1.0</ambient>
        <diffuse>0.50754 0.50754 0.50754 1.0</diffuse>
        <specular>0.508273 0.508273 0.508273 1.0</specular>
        <emissive>0.0 0.0 0.0 0.0</emissive>
      </material>
    </visual>
  </gazebo>
  <!-- TODO: check reflect parameter -->
  <!--WHEEL TIRE -->
  <joint name="robot_front_right_wheel_joint" type="continuous">
    <parent link="robot_front_right_motor_wheel"/>
    <child link="robot_front_right_wheel"/>
    <origin rpy="0 0 0" xyz="0 0 0"/>
    <axis rpy="0 0 0" xyz="0 1 0"/>
    <limit effort="1000.0" velocity="2000.0"/>
    <joint_properties damping="0.1" friction="{wheel_joint_friction}"/>
  </joint>
  <transmission name="robot_front_right_wheel_trans">
    <type>transmission_interface/SimpleTransmission</type>
    <joint name="robot_front_right_wheel_joint">
      <hardwareInterface>hardware_interface/VelocityJointInterface</hardwareInterface>
    </joint>
    <actuator name="robot_front_right_wheel_motor">
      <hardwareInterface>hardware_interface/VelocityActuatorInterface</hardwareInterface>
      <mechanicalReduction>1.0</mechanicalReduction>
    </actuator>
  </transmission>
  <link name="robot_front_right_wheel">
    <visual>
      <material name="dark-gray">
        <color rgba="0.25 0.25 0.25 1.0"/>
      </material>
      <origin rpy="0 0 3.14159265359" xyz="0 0 0"/>
      <geometry>
        <mesh filename="package://rbvogui_description/wheel_285mm.stl"/>
      </geometry>
      <material name="black_wheel">
        <color rgba="0.1 0.1 0.1 1"/>
      </material>
    </visual>
    <collision>
      <origin rpy="1.57079632679 0 0" xyz="0 0 0"/>
      <geometry>
        <sphere radius="0.1425"/>
      </geometry>
    </collision>
    <inertial>
      <mass value="4.0"/>
      <origin xyz="0 0 0"/>
      <inertia ixx="0.0268395833333" ixy="0" ixz="0" iyy="0.0268395833333" iyz="0" izz="0.0406125"/>
    </inertial>
  </link>
  <gazebo reference="robot_front_right_wheel">
    <mu1 value="1.0"/>
    <mu2 value="1.0"/>
    <kp value="10000000.0"/>
    <kd value="1.0"/>
    <visual>
      <material>
        <ambient>0.1 0.1 0.1 1.0</ambient>
        <diffuse>0.250754 0.250754 0.250754 1.0</diffuse>
        <specular>0.2508273 0.2508273 0.2508273 1.0</specular>
        <emissive>0.0 0.0 0.0 0.0</emissive>
      </material>
    </visual>
  </gazebo>
  <gazebo reference="robot_front_right_motor_wheel">
    <visual>
      <material>
        <ambient>1.0 0.0 0.0 1.0</ambient>
        <diffuse>0.50754 0.50754 0.50754 1.0</diffuse>
        <specular>0.508273 0.508273 0.508273 1.0</specular>
        <emissive>0.0 0.0 0.0 0.0</emissive>
      </material>
    </visual>
  </gazebo>
  <!--MOTOR WHEEL -->
  <joint name="robot_front_left_motor_wheel_joint" type="revolute">
    <parent link="robot_base_link"/>
    <child link="robot_front_left_motor_wheel"/>
    <origin rpy="0 0 0" xyz="0.4795 0.2925 0.0"/>
    <axis rpy="0 0 0" xyz="0 0 1"/>
    <!-- limit effort="${steer_joint_effort_limit}" velocity="${steer_joint_velocity_limit}" lower="-1.5708" upper="1.5708" / -->
    <limit effort="100.0" lower="-3.00" upper="3.00" velocity="2.83"/>
    <joint_properties damping="2.0" friction="1.0"/>
  </joint>
  <transmission name="robot_front_left_motor_wheel_trans">
    <type>transmission_interface/SimpleTransmission</type>
    <joint name="robot_front_left_motor_wheel_joint">
      <hardwareInterface>hardware_interface/PositionJointInterface</hardwareInterface>
    </joint>
    <actuator name="robot_front_left_motor_wheel_motor">
      <hardwareInterface>hardware_interface/PositionActuatorInterface</hardwareInterface>
      <mechanicalReduction>1.0</mechanicalReduction>
    </actuator>
  </transmission>
  <link name="robot_front_left_motor_wheel">
    <visual>
      <origin rpy="0 0 0" xyz="0 0 0.0"/>
      <geometry>
        <mesh filename="package://rbvogui_description/hub_rbvogui_xl.stl"/>
      </geometry>
      <material name="red">
        <color rgba="0.9 0.1 0.1 1"/>
      </material>
    </visual>
    <collision>
      <origin rpy="0 0 0" xyz="0 0 0.0"/>
      <geometry>
        <mesh filename="package://rbvogui_description/hub_rbvogui_xl.stl"/>
      </geometry>
    </collision>
    <inertial>
      <mass value="4"/>
      <origin rpy="0 0 0" xyz="0 0 0.12"/>
      <inertia ixx="0.0335494791667" ixy="0" ixz="0" iyy="0.0335494791667" iyz="0" izz="0.050765625"/>
    </inertial>
  </link>
  <gazebo reference="robot_front_left_motor_wheel">
    <visual>
      <material>
        <ambient>1.0 0.0 0.0 1.0</ambient>
        <diffuse>0.50754 0.50754 0.50754 1.0</diffuse>
        <specular>0.508273 0.508273 0.508273 1.0</specular>
        <emissive>0.0 0.0 0.0 0.0</emissive>
      </material>
    </visual>
  </gazebo>
  <!-- TODO: check reflect parameter -->
  <!--WHEEL TIRE -->
  <joint name="robot_front_left_wheel_joint" type="continuous">
    <parent link="robot_front_left_motor_wheel"/>
    <child link="robot_front_left_wheel"/>
    <origin rpy="0 0 0" xyz="0 0 0"/>
    <axis rpy="0 0 0" xyz="0 1 0"/>
    <limit effort="1000.0" velocity="2000.0"/>
    <joint_properties damping="0.1" friction="{wheel_joint_friction}"/>
  </joint>
  <transmission name="robot_front_left_wheel_trans">
    <type>transmission_interface/SimpleTransmission</type>
    <joint name="robot_front_left_wheel_joint">
      <hardwareInterface>hardware_interface/VelocityJointInterface</hardwareInterface>
    </joint>
    <actuator name="robot_front_left_wheel_motor">
      <hardwareInterface>hardware_interface/VelocityActuatorInterface</hardwareInterface>
      <mechanicalReduction>1.0</mechanicalReduction>
    </actuator>
  </transmission>
  <link name="robot_front_left_wheel">
    <visual>
      <material name="dark-gray">
        <color rgba="0.25 0.25 0.25 1.0"/>
      </material>
      <origin rpy="0 0 0" xyz="0 0 0"/>
      <geometry>
        <mesh filename="package://rbvogui_description/wheel_285mm.stl"/>
      </geometry>
      <material name="black_wheel">
        <color rgba="0.1 0.1 0.1 1"/>
      </material>
    </visual>
    <collision>
      <origin rpy="1.57079632679 0 0" xyz="0 0 0"/>
      <geometry>
        <sphere radius="0.1425"/>
      </geometry>
    </collision>
    <inertial>
      <mass value="4.0"/>
      <origin xyz="0 0 0"/>
      <inertia ixx="0.0268395833333" ixy="0" ixz="0" iyy="0.0268395833333" iyz="0" izz="0.0406125"/>
    </inertial>
  </link>
  <gazebo reference="robot_front_left_wheel">
    <mu1 value="1.0"/>
    <mu2 value="1.0"/>
    <kp value="10000000.0"/>
    <kd value="1.0"/>
    <visual>
      <material>
        <ambient>0.1 0.1 0.1 1.0</ambient>
        <diffuse>0.250754 0.250754 0.250754 1.0</diffuse>
        <specular>0.2508273 0.2508273 0.2508273 1.0</specular>
        <emissive>0.0 0.0 0.0 0.0</emissive>
      </material>
    </visual>
  </gazebo>
  <gazebo reference="robot_front_left_motor_wheel">
    <visual>
      <material>
        <ambient>1.0 0.0 0.0 1.0</ambient>
        <diffuse>0.50754 0.50754 0.50754 1.0</diffuse>
        <specular>0.508273 0.508273 0.508273 1.0</specular>
        <emissive>0.0 0.0 0.0 0.0</emissive>
      </material>
    </visual>
  </gazebo>
  <!--MOTOR WHEEL -->
  <joint name="robot_back_left_motor_wheel_joint" type="revolute">
    <parent link="robot_base_link"/>
    <child link="robot_back_left_motor_wheel"/>
    <origin rpy="0 0 0" xyz="-0.4795 0.2925 0.0"/>
    <axis rpy="0 0 0" xyz="0 0 1"/>
    <!-- limit effort="${steer_joint_effort_limit}" velocity="${steer_joint_velocity_limit}" lower="-1.5708" upper="1.5708" / -->
    <limit effort="100.0" lower="-3.00" upper="3.00" velocity="2.83"/>
    <joint_properties damping="2.0" friction="1.0"/>
  </joint>
  <transmission name="robot_back_left_motor_wheel_trans">
    <type>transmission_interface/SimpleTransmission</type>
    <joint name="robot_back_left_motor_wheel_joint">
      <hardwareInterface>hardware_interface/PositionJointInterface</hardwareInterface>
    </joint>
    <actuator name="robot_back_left_motor_wheel_motor">
      <hardwareInterface>hardware_interface/PositionActuatorInterface</hardwareInterface>
      <mechanicalReduction>1.0</mechanicalReduction>
    </actuator>
  </transmission>
  <link name="robot_back_left_motor_wheel">
    <visual>
      <origin rpy="0 0 0" xyz="0 0 0.0"/>
      <geometry>
        <mesh filename="package://rbvogui_description/hub_rbvogui_xl.stl"/>
      </geometry>
      <material name="red">
        <color rgba="0.9 0.1 0.1 1"/>
      </material>
    </visual>
    <collision>
      <origin rpy="0 0 0" xyz="0 0 0.0"/>
      <geometry>
        <mesh filename="package://rbvogui_description/hub_rbvogui_xl.stl"/>
      </geometry>
    </collision>
    <inertial>
      <mass value="4"/>
      <origin rpy="0 0 0" xyz="0 0 0.12"/>
      <inertia ixx="0.0335494791667" ixy="0" ixz="0" iyy="0.0335494791667" iyz="0" izz="0.050765625"/>
    </inertial>
  </link>
  <gazebo reference="robot_back_left_motor_wheel">
    <visual>
      <material>
        <ambient>1.0 0.0 0.0 1.0</ambient>
        <diffuse>0.50754 0.50754 0.50754 1.0</diffuse>
        <specular>0.508273 0.508273 0.508273 1.0</specular>
        <emissive>0.0 0.0 0.0 0.0</emissive>
      </material>
    </visual>
  </gazebo>
  <!-- TODO: check reflect parameter -->
  <!--WHEEL TIRE -->
  <joint name="robot_back_left_wheel_joint" type="continuous">
    <parent link="robot_back_left_motor_wheel"/>
    <child link="robot_back_left_wheel"/>
    <origin rpy="0 0 0" xyz="0 0 0"/>
    <axis rpy="0 0 0" xyz="0 1 0"/>
    <limit effort="1000.0" velocity="2000.0"/>
    <joint_properties damping="0.1" friction="{wheel_joint_friction}"/>
  </joint>
  <transmission name="robot_back_left_wheel_trans">
    <type>transmission_interface/SimpleTransmission</type>
    <joint name="robot_back_left_wheel_joint">
      <hardwareInterface>hardware_interface/VelocityJointInterface</hardwareInterface>
    </joint>
    <actuator name="robot_back_left_wheel_motor">
      <hardwareInterface>hardware_interface/VelocityActuatorInterface</hardwareInterface>
      <mechanicalReduction>1.0</mechanicalReduction>
    </actuator>
  </transmission>
  <link name="robot_back_left_wheel">
    <visual>
      <material name="dark-gray">
        <color rgba="0.25 0.25 0.25 1.0"/>
      </material>
      <origin rpy="0 0 0" xyz="0 0 0"/>
      <geometry>
        <mesh filename="package://rbvogui_description/wheel_285mm.stl"/>
      </geometry>
      <material name="black_wheel">
        <color rgba="0.1 0.1 0.1 1"/>
      </material>
    </visual>
    <collision>
      <origin rpy="1.57079632679 0 0" xyz="0 0 0"/>
      <geometry>
        <sphere radius="0.1425"/>
      </geometry>
    </collision>
    <inertial>
      <mass value="4.0"/>
      <origin xyz="0 0 0"/>
      <inertia ixx="0.0268395833333" ixy="0" ixz="0" iyy="0.0268395833333" iyz="0" izz="0.0406125"/>
    </inertial>
  </link>
  <gazebo reference="robot_back_left_wheel">
    <mu1 value="1.0"/>
    <mu2 value="1.0"/>
    <kp value="10000000.0"/>
    <kd value="1.0"/>
    <visual>
      <material>
        <ambient>0.1 0.1 0.1 1.0</ambient>
        <diffuse>0.250754 0.250754 0.250754 1.0</diffuse>
        <specular>0.2508273 0.2508273 0.2508273 1.0</specular>
        <emissive>0.0 0.0 0.0 0.0</emissive>
      </material>
    </visual>
  </gazebo>
  <gazebo reference="robot_back_left_motor_wheel">
    <visual>
      <material>
        <ambient>1.0 0.0 0.0 1.0</ambient>
        <diffuse>0.50754 0.50754 0.50754 1.0</diffuse>
        <specular>0.508273 0.508273 0.508273 1.0</specular>
        <emissive>0.0 0.0 0.0 0.0</emissive>
      </material>
    </visual>
  </gazebo>
  <!--MOTOR WHEEL -->
  <joint name="robot_back_right_motor_wheel_joint" type="revolute">
    <parent link="robot_base_link"/>
    <child link="robot_back_right_motor_wheel"/>
    <origin rpy="0 0 0" xyz="-0.4795 -0.2925 0.0"/>
    <axis rpy="0 0 0" xyz="0 0 1"/>
    <!-- limit effort="${steer_joint_effort_limit}" velocity="${steer_joint_velocity_limit}" lower="-1.5708" upper="1.5708" / -->
    <limit effort="100.0" lower="-3.00" upper="3.00" velocity="2.83"/>
    <joint_properties damping="2.0" friction="1.0"/>
  </joint>
  <transmission name="robot_back_right_motor_wheel_trans">
    <type>transmission_interface/SimpleTransmission</type>
    <joint name="robot_back_right_motor_wheel_joint">
      <hardwareInterface>hardware_interface/PositionJointInterface</hardwareInterface>
    </joint>
    <actuator name="robot_back_right_motor_wheel_motor">
      <hardwareInterface>hardware_interface/PositionActuatorInterface</hardwareInterface>
      <mechanicalReduction>1.0</mechanicalReduction>
    </actuator>
  </transmission>
  <link name="robot_back_right_motor_wheel">
    <visual>
      <origin rpy="0 0 3.14159265359" xyz="0 0 0"/>
      <geometry>
        <mesh filename="package://rbvogui_description/hub_rbvogui_xl.stl"/>
      </geometry>
      <material name="red">
        <color rgba="0.9 0.1 0.1 1"/>
      </material>
    </visual>
    <collision>
      <origin rpy="0 0 3.14159265359" xyz="0 0 0"/>
      <geometry>
        <mesh filename="package://rbvogui_description/hub_rbvogui_xl.stl"/>
      </geometry>
    </collision>
    <inertial>
      <mass value="4"/>
      <origin rpy="0 0 3.14159265359" xyz="0 0 0.12"/>
      <inertia ixx="0.0335494791667" ixy="0" ixz="0" iyy="0.0335494791667" iyz="0" izz="0.050765625"/>
    </inertial>
  </link>
  <gazebo reference="robot_back_right_motor_wheel">
    <visual>
      <material>
        <ambient>1.0 0.0 0.0 1.0</ambient>
        <diffuse>0.50754 0.50754 0.50754 1.0</diffuse>
        <specular>0.508273 0.508273 0.508273 1.0</specular>
        <emissive>0.0 0.0 0.0 0.0</emissive>
      </material>
    </visual>
  </gazebo>
  <!-- TODO: check reflect parameter -->
  <!--WHEEL TIRE -->
  <joint name="robot_back_right_wheel_joint" type="continuous">
    <parent link="robot_back_right_motor_wheel"/>
    <child link="robot_back_right_wheel"/>
    <origin rpy="0 0 0" xyz="0 0 0"/>
    <axis rpy="0 0 0" xyz="0 1 0"/>
    <limit effort="1000.0" velocity="2000.0"/>
    <joint_properties damping="0.1" friction="{wheel_joint_friction}"/>
  </joint>
  <transmission name="robot_back_right_wheel_trans">
    <type>transmission_interface/SimpleTransmission</type>
    <joint name="robot_back_right_wheel_joint">
      <hardwareInterface>hardware_interface/VelocityJointInterface</hardwareInterface>
    </joint>
    <actuator name="robot_back_right_wheel_motor">
      <hardwareInterface>hardware_interface/VelocityActuatorInterface</hardwareInterface>
      <mechanicalReduction>1.0</mechanicalReduction>
    </actuator>
  </transmission>
  <link name="robot_back_right_wheel">
    <visual>
      <material name="dark-gray">
        <color rgba="0.25 0.25 0.25 1.0"/>
      </material>
      <origin rpy="0 0 3.14159265359" xyz="0 0 0"/>
      <geometry>
        <mesh filename="package://rbvogui_description/wheel_285mm.stl"/>
      </geometry>
      <material name="black_wheel">
        <color rgba="0.1 0.1 0.1 1"/>
      </material>
    </visual>
    <collision>
      <origin rpy="1.57079632679 0 0" xyz="0 0 0"/>
      <geometry>
        <sphere radius="0.1425"/>
      </geometry>
    </collision>
    <inertial>
      <mass value="4.0"/>
      <origin xyz="0 0 0"/>
      <inertia ixx="0.0268395833333" ixy="0" ixz="0" iyy="0.0268395833333" iyz="0" izz="0.0406125"/>
    </inertial>
  </link>
  <gazebo reference="robot_back_right_wheel">
    <mu1 value="1.0"/>
    <mu2 value="1.0"/>
    <kp value="10000000.0"/>
    <kd value="1.0"/>
    <visual>
      <material>
        <ambient>0.1 0.1 0.1 1.0</ambient>
        <diffuse>0.250754 0.250754 0.250754 1.0</diffuse>
        <specular>0.2508273 0.2508273 0.2508273 1.0</specular>
        <emissive>0.0 0.0 0.0 0.0</emissive>
      </material>
    </visual>
  </gazebo>
  <gazebo reference="robot_back_right_motor_wheel">
    <visual>
      <material>
        <ambient>1.0 0.0 0.0 1.0</ambient>
        <diffuse>0.50754 0.50754 0.50754 1.0</diffuse>
        <specular>0.508273 0.508273 0.508273 1.0</specular>
        <emissive>0.0 0.0 0.0 0.0</emissive>
      </material>
    </visual>
  </gazebo>
  <!-- Lift base link -->
  <link name="robot_ewellix_lift_base_link">
    <visual>
      <origin rpy="0 0 0" xyz="0 0 -0.0526"/>
      <geometry>
        <mesh filename="package://ewellix_description/ewellix_lift_base_700mm.stl"/>
      </geometry>
      <material name="grey">
        <color rgba="0.7 0.7 0.7 1"/>
      </material>
    </visual>
    <collision>
      <origin rpy="0 0 0" xyz="-0.005 0 0.00235"/>
      <geometry>
        <mesh filename="package://ewellix_description/ewellix_lift_base_700mm.stl"/>
      </geometry>
    </collision>
    <inertial>
      <mass value="20"/>
      <origin rpy="0 0 0" xyz="0 0 0"/>
      <inertia ixx="1e-1" ixy="0" ixz="0" iyy="1e-1" iyz="0" izz="1e-1"/>
    </inertial>
  </link>
  <!-- Lift base link joint -->
  <joint name="robot_ewellix_lift_base_joint" type="fixed">
    <origin rpy="0 0 0" xyz="0.275 0.0 0.01"/>
    <parent link="robot_chassis_link"/>
    <child link="robot_ewellix_lift_base_link"/>
  </joint>
  <!-- Lift top link -->
  <link name="robot_ewellix_lift_top_link">
    <visual>
      <origin rpy="0 0 0" xyz="0 0 0.015"/>
      <geometry>
        <mesh filename="package://ewellix_description/ewellix_lift_top_700mm.stl"/>
      </geometry>
      <material name="grey">
        <color rgba="0.7 0.7 0.7 1"/>
      </material>
    </visual>
    <collision>
      <origin rpy="0 0 0" xyz="-0.005 0 0.00235"/>
      <geometry>
        <mesh filename="package://ewellix_description/ewellix_lift_top_700mm.stl"/>
      </geometry>
    </collision>
    <inertial>
      <mass value="2"/>
      <origin rpy="0 0 0" xyz="0 0 0"/>
      <inertia ixx="0.2e-1" ixy="0" ixz="0" iyy="0.2e-1" iyz="0" izz="0.2e-1"/>
    </inertial>
  </link>
  <!-- Lift top link joint -->
  <joint name="robot_ewellix_lift_top_joint" type="prismatic">
    <parent link="robot_ewellix_lift_base_link"/>
    <child link="robot_ewellix_lift_top_link"/>
    <origin rpy="0 0 0" xyz="0 0 0.620"/>
    <limit effort="1000" lower="0.0" upper="0.7" velocity="0.088"/>
    <axis xyz="0 0 1"/>
  </joint>
  <!--
        PositionJointInterface
        VelocityJointInterface
        EffortJointInterface
    -->
  <transmission name="robot_ewellix_lift_top_trans" type="SimpleTransmission">
    <type>transmission_interface/SimpleTransmission</type>
    <actuator name="robot_ewellix_lift_top_joint_motor">
      <mechanicalReduction>1</mechanicalReduction>
    </actuator>
    <joint name="robot_ewellix_lift_top_joint">
      <hardwareInterface>hardware_interface/PositionJointInterface</hardwareInterface>
    </joint>
  </transmission>
  <gazebo reference="robot_ewellix_lift_base_link">
    <material>Gazebo/Grey</material>
  </gazebo>
  <gazebo reference="robot_ewellix_lift_top_link">
    <material>Gazebo/Grey</material>
  </gazebo>
  <!--
    Base UR robot series xacro macro.

    NOTE: this is NOT a URDF. It cannot directly be loaded by consumers
    expecting a flattened '.urdf' file. See the top-level '.xacro' for that
    (but note: that .xacro must still be processed by the xacro command).

    For use in '.launch' files: use one of the 'load_urX.launch' convenience
    launch files.

    This file models the base kinematic chain of a UR robot, which then gets
    parameterised by various configuration files to convert it into a UR3(e),
    UR5(e), UR10(e) or UR16e.

    NOTE: the default kinematic parameters (ie: link lengths, frame locations,
    offets, etc) do not correspond to any particular robot. They are defaults
    only. There WILL be non-zero offsets between the Forward Kinematics results
    in TF (ie: robot_state_publisher) and the values reported by the Teach
    Pendant.

    For accurate (and robot-specific) transforms, the 'kinematics_parameters_file'
    parameter MUST point to a .yaml file containing the appropriate values for
    the targetted robot.

    If using the UniversalRobots/Universal_Robots_ROS_Driver, follow the steps
    described in the readme of that repository to extract the kinematic
    calibration from the controller and generate the required .yaml file.

    Main author of the migration to yaml configs: Ludovic Delval.

    Contributors to previous versions (in no particular order):

     - Felix Messmer
     - Kelsey Hawkins
     - Wim Meeussen
     - Shaun Edwards
     - Nadia Hammoudeh Garcia
     - Dave Hershberger
     - G. vd. Hoorn
     - Philip Long
     - Dave Coleman
     - Miguel Prada
     - Mathias Luedtke
     - Marcel Schnirring
     - Felix von Drigalski
     - Felix Exner
     - Jimmy Da Silva
     - Ajit Krisshna N L
     - Muhammad Asif Rana
  -->
  <!--
    NOTE: the macro defined in this file is NOT part of the public API of this
          package. Users CANNOT rely on this file being available, or stored in
          this location. Nor can they rely on the existence of the macro.
  -->
  <transmission name="robot_arm_shoulder_pan_trans">
    <type>transmission_interface/SimpleTransmission</type>
    <joint name="robot_arm_shoulder_pan_joint">
      <hardwareInterface>hardware_interface/PositionJointInterface</hardwareInterface>
    </joint>
    <actuator name="robot_arm_shoulder_pan_motor">
      <mechanicalReduction>1</mechanicalReduction>
    </actuator>
  </transmission>
  <transmission name="robot_arm_shoulder_lift_trans">
    <type>transmission_interface/SimpleTransmission</type>
    <joint name="robot_arm_shoulder_lift_joint">
      <hardwareInterface>hardware_interface/PositionJointInterface</hardwareInterface>
    </joint>
    <actuator name="robot_arm_shoulder_lift_motor">
      <mechanicalReduction>1</mechanicalReduction>
    </actuator>
  </transmission>
  <transmission name="robot_arm_elbow_trans">
    <type>transmission_interface/SimpleTransmission</type>
    <joint name="robot_arm_elbow_joint">
      <hardwareInterface>hardware_interface/PositionJointInterface</hardwareInterface>
    </joint>
    <actuator name="robot_arm_elbow_motor">
      <mechanicalReduction>1</mechanicalReduction>
    </actuator>
  </transmission>
  <transmission name="robot_arm_wrist_1_trans">
    <type>transmission_interface/SimpleTransmission</type>
    <joint name="robot_arm_wrist_1_joint">
      <hardwareInterface>hardware_interface/PositionJointInterface</hardwareInterface>
    </joint>
    <actuator name="robot_arm_wrist_1_motor">
      <mechanicalReduction>1</mechanicalReduction>
    </actuator>
  </transmission>
  <transmission name="robot_arm_wrist_2_trans">
    <type>transmission_interface/SimpleTransmission</type>
    <joint name="robot_arm_wrist_2_joint">
      <hardwareInterface>hardware_interface/PositionJointInterface</hardwareInterface>
    </joint>
    <actuator name="robot_arm_wrist_2_motor">
      <mechanicalReduction>1</mechanicalReduction>
    </actuator>
  </transmission>
  <transmission name="robot_arm_wrist_3_trans">
    <type>transmission_interface/SimpleTransmission</type>
    <joint name="robot_arm_wrist_3_joint">
      <hardwareInterface>hardware_interface/PositionJointInterface</hardwareInterface>
    </joint>
    <actuator name="robot_arm_wrist_3_motor">
      <mechanicalReduction>1</mechanicalReduction>
    </actuator>
  </transmission>
  <!-- links: main serial chain -->
  <link name="robot_arm_base_link"/>
  <link name="robot_arm_base_link_inertia">
    <visual>
      <origin rpy="0 0 3.14159265359" xyz="0 0 0"/>
      <geometry>
        <mesh filename="package://ur_e_description/meshes/ur10e/visual/base.obj"/>
      </geometry>
      <material name="LightGrey">
        <color rgba="0.7 0.7 0.7 1.0"/>
      </material>
    </visual>
    <collision>
      <origin rpy="0 0 3.14159265359" xyz="0 0 0"/>
      <geometry>
        <mesh filename="package://ur_e_description/meshes/ur10e/collision/base.stl"/>
      </geometry>
    </collision>
    <inertial>
      <mass value="4.0"/>
      <origin rpy="0 0 0" xyz="0 0 0"/>
      <inertia ixx="0.0061063308908" ixy="0.0" ixz="0.0" iyy="0.0061063308908" iyz="0.0" izz="0.01125"/>
    </inertial>
  </link>
  <link name="robot_arm_shoulder_link">
    <visual>
      <origin rpy="0 0 3.14159265359" xyz="0 0 0"/>
      <geometry>
        <mesh filename="package://ur_e_description/meshes/ur10e/visual/shoulder.obj"/>
      </geometry>
      <material name="LightGrey">
        <color rgba="0.7 0.7 0.7 1.0"/>
      </material>
    </visual>
    <collision>
      <origin rpy="0 0 3.14159265359" xyz="0 0 0"/>
      <geometry>
        <mesh filename="package://ur_e_description/meshes/ur10e/collision/shoulder.stl"/>
      </geometry>
    </collision>
    <inertial>
      <mass value="7.778"/>
      <origin rpy="0 0 0" xyz="0 0 0"/>
      <inertia ixx="0.0314743125769" ixy="0.0" ixz="0.0" iyy="0.0314743125769" iyz="0.0" izz="0.021875625"/>
    </inertial>
  </link>
  <link name="robot_arm_upper_arm_link">
    <visual>
      <origin rpy="1.57079632679 0 -1.57079632679" xyz="0 0 0.1762"/>
      <geometry>
        <mesh filename="package://ur_e_description/meshes/ur10e/visual/upperarm.obj"/>
      </geometry>
      <material name="LightGrey">
        <color rgba="0.7 0.7 0.7 1.0"/>
      </material>
    </visual>
    <collision>
      <origin rpy="1.57079632679 0 -1.57079632679" xyz="0 0 0.1762"/>
      <geometry>
        <mesh filename="package://ur_e_description/meshes/ur10e/collision/upperarm.stl"/>
      </geometry>
    </collision>
    <inertial>
      <mass value="12.93"/>
      <origin rpy="0 1.57079632679 0" xyz="-0.306 0.0 0.175"/>
      <inertia ixx="0.421753803798" ixy="0.0" ixz="0.0" iyy="0.421753803798" iyz="0.0" izz="0.036365625"/>
    </inertial>
  </link>
  <link name="robot_arm_forearm_link">
    <visual>
      <origin rpy="1.57079632679 0 -1.57079632679" xyz="0 0 0.0393"/>
      <geometry>
        <mesh filename="package://ur_e_description/meshes/ur10e/visual/forearm.obj"/>
      </geometry>
      <material name="LightGrey">
        <color rgba="0.7 0.7 0.7 1.0"/>
      </material>
    </visual>
    <collision>
      <origin rpy="1.57079632679 0 -1.57079632679" xyz="0 0 0.0393"/>
      <geometry>
        <mesh filename="package://ur_e_description/meshes/ur10e/collision/forearm.stl"/>
      </geometry>
    </collision>
    <inertial>
      <mass value="3.87"/>
      <origin rpy="0 1.57079632679 0" xyz="-0.285775 0.0 0.0393"/>
      <inertia ixx="0.110793025489" ixy="0.0" ixz="0.0" iyy="0.110793025489" iyz="0.0" izz="0.010884375"/>
    </inertial>
  </link>
  <link name="robot_arm_wrist_1_link">
    <visual>
      <!-- TODO: Move this to a parameter -->
      <origin rpy="1.57079632679 0 0" xyz="0 0 -0.135"/>
      <geometry>
        <mesh filename="package://ur_e_description/meshes/ur10e/visual/wrist1.obj"/>
      </geometry>
      <material name="LightGrey">
        <color rgba="0.7 0.7 0.7 1.0"/>
      </material>
    </visual>
    <collision>
      <origin rpy="1.57079632679 0 0" xyz="0 0 -0.135"/>
      <geometry>
        <mesh filename="package://ur_e_description/meshes/ur10e/collision/wrist1.stl"/>
      </geometry>
    </collision>
    <inertial>
      <mass value="1.96"/>
      <origin rpy="0 0 0" xyz="0 0 0"/>
      <inertia ixx="0.0051082479567" ixy="0.0" ixz="0.0" iyy="0.0051082479567" iyz="0.0" izz="0.0055125"/>
    </inertial>
  </link>
  <link name="robot_arm_wrist_2_link">
    <visual>
      <origin rpy="0 0 0" xyz="0 0 -0.12"/>
      <geometry>
        <mesh filename="package://ur_e_description/meshes/ur10e/visual/wrist2.obj"/>
      </geometry>
      <material name="LightGrey">
        <color rgba="0.7 0.7 0.7 1.0"/>
      </material>
    </visual>
    <collision>
      <origin rpy="0 0 0" xyz="0 0 -0.12"/>
      <geometry>
        <mesh filename="package://ur_e_description/meshes/ur10e/collision/wrist2.stl"/>
      </geometry>
    </collision>
    <inertial>
      <mass value="1.96"/>
      <origin rpy="0 0 0" xyz="0 0 0"/>
      <inertia ixx="0.0051082479567" ixy="0.0" ixz="0.0" iyy="0.0051082479567" iyz="0.0" izz="0.0055125"/>
    </inertial>
  </link>
  <link name="robot_arm_wrist_3_link">
    <visual>
      <origin rpy="1.57079632679 0 0" xyz="0 0 -0.1168"/>
      <geometry>
        <mesh filename="package://ur_e_description/meshes/ur10e/visual/wrist3.obj"/>
      </geometry>
      <material name="LightGrey">
        <color rgba="0.7 0.7 0.7 1.0"/>
      </material>
    </visual>
    <collision>
      <origin rpy="1.57079632679 0 0" xyz="0 0 -0.1168"/>
      <geometry>
        <mesh filename="package://ur_e_description/meshes/ur10e/collision/wrist3.stl"/>
      </geometry>
    </collision>
    <inertial>
      <mass value="0.202"/>
      <origin rpy="0 0 0" xyz="0.0 0.0 -0.025"/>
      <inertia ixx="0.000144345775595" ixy="0.0" ixz="0.0" iyy="0.000144345775595" iyz="0.0" izz="0.000204525"/>
    </inertial>
  </link>
  <!-- joints: main serial chain -->
  <joint name="robot_arm_base_link-base_link_inertia" type="fixed">
    <parent link="robot_arm_base_link"/>
    <child link="robot_arm_base_link_inertia"/>
    <!-- 'base_link' is REP-103 aligned (so X+ forward), while the internal
           frames of the robot/controller have X+ pointing backwards.
           Use the joint between 'base_link' and 'base_link_inertia' (a dummy
           link/frame) to introduce the necessary rotation over Z (of pi rad).
      -->
    <origin rpy="0 0 0" xyz="0 0 0"/>
  </joint>
  <joint name="robot_arm_shoulder_pan_joint" type="revolute">
    <parent link="robot_arm_base_link_inertia"/>
    <child link="robot_arm_shoulder_link"/>
    <origin rpy="0 0 0" xyz="0 0 0.1807"/>
    <axis xyz="0 0 1"/>
    <limit effort="330.0" lower="-6.28318530718" upper="6.28318530718" velocity="2.09439510239"/>
    <dynamics damping="0" friction="0"/>
  </joint>
  <joint name="robot_arm_shoulder_lift_joint" type="revolute">
    <parent link="robot_arm_shoulder_link"/>
    <child link="robot_arm_upper_arm_link"/>
    <origin rpy="1.570796327 0 0" xyz="0 0 0"/>
    <axis xyz="0 0 1"/>
    <limit effort="330.0" lower="-6.28318530718" upper="6.28318530718" velocity="2.09439510239"/>
    <dynamics damping="0" friction="0"/>
  </joint>
  <joint name="robot_arm_elbow_joint" type="revolute">
    <parent link="robot_arm_upper_arm_link"/>
    <child link="robot_arm_forearm_link"/>
    <origin rpy="0 0 0" xyz="-0.6127 0 0"/>
    <axis xyz="0 0 1"/>
    <limit effort="150.0" lower="-3.14159265359" upper="3.14159265359" velocity="3.14159265359"/>
    <dynamics damping="0" friction="0"/>
  </joint>
  <joint name="robot_arm_wrist_1_joint" type="revolute">
    <parent link="robot_arm_forearm_link"/>
    <child link="robot_arm_wrist_1_link"/>
    <origin rpy="0 0 0" xyz="-0.57155 0 0.17415"/>
    <axis xyz="0 0 1"/>
    <limit effort="56.0" lower="-6.28318530718" upper="6.28318530718" velocity="3.14159265359"/>
    <dynamics damping="0" friction="0"/>
  </joint>
  <joint name="robot_arm_wrist_2_joint" type="revolute">
    <parent link="robot_arm_wrist_1_link"/>
    <child link="robot_arm_wrist_2_link"/>
    <origin rpy="1.570796327 0 0" xyz="0 -0.11985 -2.45816459076e-11"/>
    <axis xyz="0 0 1"/>
    <limit effort="56.0" lower="-6.28318530718" upper="6.28318530718" velocity="3.14159265359"/>
    <dynamics damping="0" friction="0"/>
  </joint>
  <joint name="robot_arm_wrist_3_joint" type="revolute">
    <parent link="robot_arm_wrist_2_link"/>
    <child link="robot_arm_wrist_3_link"/>
    <origin rpy="1.57079632659 3.14159265359 3.14159265359" xyz="0 0.11655 -2.39048045935e-11"/>
    <axis xyz="0 0 1"/>
    <limit effort="56.0" lower="-6.28318530718" upper="6.28318530718" velocity="3.14159265359"/>
    <dynamics damping="0" friction="0"/>
  </joint>
  <!-- ROS-Industrial 'base' frame: base_link to UR 'Base' Coordinates transform -->
  <link name="robot_arm_base"/>
  <joint name="robot_arm_base_link-base_fixed_joint" type="fixed">
    <!-- Note the rotation over Z of pi radians: as base_link is REP-103
           aligned (ie: has X+ forward, Y+ left and Z+ up), this is needed
           to correctly align 'base' with the 'Base' coordinate system of
           the UR controller.
      -->
    <origin rpy="0 0 3.14159265359" xyz="0 0 0"/>
    <parent link="robot_arm_base_link"/>
    <child link="robot_arm_base"/>
  </joint>
  <!-- ROS-Industrial 'flange' frame: attachment point for EEF models -->
  <link name="robot_arm_flange"/>
  <joint name="robot_arm_wrist_3-flange" type="fixed">
    <parent link="robot_arm_wrist_3_link"/>
    <child link="robot_arm_flange"/>
    <origin rpy="0 -1.57079632679 -1.57079632679" xyz="0 0 0"/>
  </joint>
  <!-- ROS-Industrial 'tool0' frame: all-zeros tool frame -->
  <link name="robot_arm_tool0"/>
  <joint name="robot_arm_flange-tool0" type="fixed">
    <!-- default toolframe: X+ left, Y+ up, Z+ front -->
    <origin rpy="1.57079632679 0 1.57079632679" xyz="0 0 0"/>
    <parent link="robot_arm_flange"/>
    <child link="robot_arm_tool0"/>
  </joint>
  <joint name="robot_arm_base_joint" type="fixed">
    <origin rpy="0 0 2.35619449019" xyz="0 0 0.015"/>
    <parent link="robot_ewellix_lift_top_link"/>
    <child link="robot_arm_base_link"/>
  </joint>
  <!-- SENSORS see robotnik_sensors for the specific configuration -->
  <joint name="robot_imu_base_joint" type="fixed">
    <axis xyz="1 0 0"/>
    <!--origin xyz="0 0 0.2825"/-->
    <origin rpy="0 0 0" xyz="0.3 -0.3 0.0725"/>
    <parent link="robot_chassis_link"/>
    <child link="robot_imu_base_link"/>
  </joint>
  <link name="robot_imu_base_link">
    <inertial>
      <origin rpy="0 0 0" xyz="0.0 0 0.01"/>
      <mass value="0.05"/>
      <inertia ixx="3.33333333333e-06" ixy="0" ixz="0" iyy="3.33333333333e-06" iyz="0" izz="3.33333333333e-06"/>
    </inertial>
    <visual>
      <origin rpy="0 0 0" xyz="0 0 0"/>
      <material name="vectornav_imu_color">
        <color rgba="1 0 0 1"/>
      </material>
      <geometry>
        <mesh filename="package://robotnik_sensors/meshes/vectornav_vn100.stl"/>
      </geometry>
    </visual>
    <collision>
      <origin rpy="0 0 0" xyz="0 0 0.0045"/>
      <geometry>
        <box size="0.036 0.037 0.009"/>
      </geometry>
    </collision>
  </link>
  <joint name="robot_imu_joint" type="fixed">
    <axis xyz="1 0 0"/>
    <origin xyz="0.00671 0.0047 0.0059"/>
    <parent link="robot_imu_base_link"/>
    <child link="robot_imu_link"/>
  </joint>
  <link name="robot_imu_link">
	  </link>
  <gazebo reference="robot_imu_base_link">
    <material>Gazebo/Red</material>
  </gazebo>
  <gazebo>
    <plugin filename="libhector_gazebo_ros_imu.so" name="robot_imu_controller">
      <alwaysOn>true</alwaysOn>
      <topicName>imu/data</topicName>
      <serviceName>robot_imuimu/service</serviceName>
      <bodyName>robot_imu_link</bodyName>
      <frameId>robot_imu_link</frameId>
      <updateRate>50.0</updateRate>
      <gaussianNoise>0.00</gaussianNoise>
      <yawOffset>0.0</yawOffset>
      <yawDrift>0.0</yawDrift>
      <yawGaussianNoise>0.0</yawGaussianNoise>
      <!-- angular velocities parameters -->
      <rateOffset>0.0 0.0 0.0</rateOffset>
      <rateDrift>0.0 0.0 0.0</rateDrift>
      <rateGaussianNoise>0.0 0.0 0.0</rateGaussianNoise>
      <!-- linear accelerations parameters -->
      <accelOffset>0.0 0.0 0.0</accelOffset>
      <accelDrift>0.0 0.0 0.0</accelDrift>
      <accelGaussianNoise>0.0 0.0 0.0</accelGaussianNoise>
    </plugin>
  </gazebo>
  <joint name="robot_front_rgbd_camera_joint" type="fixed">
    <origin rpy="0 0 0" xyz="0.637 0.0 -0.036"/>
    <parent link="robot_chassis_link"/>
    <child link="robot_front_rgbd_camera_link"/>
  </joint>
  <link name="robot_front_rgbd_camera_link">
    <visual>
      <origin rpy="0 0 0" xyz="0 0 0"/>
      <geometry>
        <mesh filename="package://robotnik_sensors/meshes/orbbec_astra.stl"/>
      </geometry>
    </visual>
    <collision>
      <geometry>
        <mesh filename="package://robotnik_sensors/meshes/orbbec_astra.stl"/>
      </geometry>
    </collision>
    <inertial>
      <mass value="0.001"/>
      <origin xyz="0.0 0.0 0.0"/>
      <inertia ixx="2.34375e-06" ixy="0" ixz="0" iyy="2.08333333333e-07" iyz="0" izz="2.40208333333e-06"/>
    </inertial>
  </link>
  <joint name="robot_front_rgbd_camera_rgb_joint" type="fixed">
    <origin rpy="0.0 0.0 0.0" xyz="0.0 0.0125 0.0150"/>
    <parent link="robot_front_rgbd_camera_link"/>
    <child link="robot_front_rgbd_camera_rgb_frame"/>
  </joint>
  <link name="robot_front_rgbd_camera_rgb_frame">
    <inertial>
      <mass value="0.297"/>
      <origin xyz="-0.02 -0.0125 0.0"/>
      <inertia ixx="0.00069609375" ixy="0" ixz="0" iyy="6.1875e-05" iyz="0" izz="0.00071341875"/>
    </inertial>
  </link>
  <joint name="robot_front_rgbd_camera_rgb_optical_joint" type="fixed">
    <origin rpy="-1.57079632679 0 -1.57079632679" xyz="0.0 0.0 0.0"/>
    <parent link="robot_front_rgbd_camera_rgb_frame"/>
    <child link="robot_front_rgbd_camera_rgb_optical_frame"/>
  </joint>
  <link name="robot_front_rgbd_camera_rgb_optical_frame">
    <inertial>
      <mass value="0.001"/>
      <origin rpy="1.57079632679 0 1.57079632679" xyz="0 0 0"/>
      <inertia ixx="2.34375e-06" ixy="0" ixz="0" iyy="2.08333333333e-07" iyz="0" izz="2.40208333333e-06"/>
    </inertial>
  </link>
  <joint name="robot_front_rgbd_camera_depth_joint" type="fixed">
    <origin rpy="0 0 0" xyz="0.0 0.0375 0.0150"/>
    <parent link="robot_front_rgbd_camera_link"/>
    <child link="robot_front_rgbd_camera_depth_frame"/>
  </joint>
  <link name="robot_front_rgbd_camera_depth_frame">
    <inertial>
      <mass value="0.001"/>
      <origin xyz="0 0 0"/>
      <inertia ixx="2.34375e-06" ixy="0" ixz="0" iyy="2.08333333333e-07" iyz="0" izz="2.40208333333e-06"/>
    </inertial>
  </link>
  <joint name="robot_front_rgbd_camera_depth_optical_joint" type="fixed">
    <origin rpy="-1.57079632679 0 -1.57079632679" xyz="0 0 0"/>
    <parent link="robot_front_rgbd_camera_depth_frame"/>
    <child link="robot_front_rgbd_camera_depth_optical_frame"/>
  </joint>
  <link name="robot_front_rgbd_camera_depth_optical_frame">
    <inertial>
      <mass value="0.001"/>
      <origin xyz="0 0 0"/>
      <inertia ixx="2.34375e-06" ixy="0" ixz="0" iyy="2.08333333333e-07" iyz="0" izz="2.40208333333e-06"/>
    </inertial>
  </link>
  <gazebo reference="robot_front_rgbd_camera_link">
    <sensor name="robot_front_rgbd_camera_depth_sensor" type="depth">
      <always_on>true</always_on>
      <update_rate>20.0</update_rate>
      <camera>
        <horizontal_fov>1.0471975512</horizontal_fov>
        <image>
          <format>R8G8B8</format>
          <width>640</width>
          <height>480</height>
        </image>
        <clip>
          <near>0.05</near>
          <far>3.5</far>
        </clip>
      </camera>
      <plugin filename="libgazebo_ros_openni_kinect.so" name="robot_front_rgbd_camera_controller">
        <cameraName>front_rgbd_camera</cameraName>
        <alwaysOn>true</alwaysOn>
        <updateRate>10</updateRate>
        <imageTopicName>rgb/image_raw</imageTopicName>
        <depthImageTopicName>depth/image_raw</depthImageTopicName>
        <pointCloudTopicName>depth/points</pointCloudTopicName>
        <cameraInfoTopicName>rgb/camera_info</cameraInfoTopicName>
        <depthImageCameraInfoTopicName>depth/camera_info</depthImageCameraInfoTopicName>
        <frameName>/robot_front_rgbd_camera_depth_optical_frame</frameName>
        <baseline>0.1</baseline>
        <distortion_k1>0.0</distortion_k1>
        <distortion_k2>0.0</distortion_k2>
        <distortion_k3>0.0</distortion_k3>
        <distortion_t1>0.0</distortion_t1>
        <distortion_t2>0.0</distortion_t2>
        <pointCloudCutoff>0.4</pointCloudCutoff>
      </plugin>
    </sensor>
  </gazebo>
  <!-- Zed camera 
        <xacro:sensor_zed prefix="${prefix}zed" parent="${prefix}chassis_link" model="zed2">
            <origin xyz="0.63658 0.0 -0.03643" rpy="0 0 0"/>
        </xacro:sensor_zed>  
        -->
  <joint name="robot_front_3d_laser_base_joint" type="fixed">
    <origin rpy="0 1.57079632679 0" xyz="0.579 0 0.241"/>
    <parent link="robot_chassis_link"/>
    <child link="robot_front_3d_laser_base_link"/>
  </joint>
  <link name="robot_front_3d_laser_base_link">
    <visual>
      <!-- origin xyz="0 0 0" rpy="0 0 1.5708"/ -->
      <origin rpy="0 0 0" xyz="0 0 0"/>
      <geometry>
        <mesh filename="package://robotnik_sensors/meshes/rs_bpearl.stl"/>
      </geometry>
      <material name="blackgray_color">
        <color rgba="0.25 0.25 0.25 1"/>
      </material>
    </visual>
    <collision>
      <origin rpy="0 0 0" xyz="0 0 0"/>
      <geometry>
        <mesh filename="package://robotnik_sensors/meshes/rs_bpearl.stl"/>
      </geometry>
    </collision>
    <inertial>
      <!-- The following are not reliable values, and should not be used for modeling -->
      <mass value="0.92"/>
      <origin xyz="0 0 0.055"/>
      <inertia ixx="0.00187227666667" ixy="0" ixz="0" iyy="0.00187227666667" iyz="0" izz="0.00188922"/>
    </inertial>
  </link>
  <joint name="robot_front_3d_laser_joint" type="fixed">
    <parent link="robot_front_3d_laser_base_link"/>
    <child link="robot_front_3d_laser_link"/>
    <origin rpy="0 0 0" xyz="0 0 0.09427"/>
  </joint>
  <link name="robot_front_3d_laser_link"/>
  <gazebo reference="robot_front_3d_laser_base_link">
    <visual>
      <material>
        <ambient>0.5 0.5 0.5 1.0</ambient>
        <diffuse>0.250754 0.250754 0.250754 1.0</diffuse>
        <specular>0.2508273 0.2508273 0.2508273 1.0</specular>
        <emissive>0.0 0.0 0.0 0.0</emissive>
      </material>
    </visual>
  </gazebo>
  <gazebo reference="robot_front_3d_laser_link">
    <visual>
      <material>
        <ambient>1.2 0.2 0.2 1.0</ambient>
        <diffuse>0.250754 0.250754 0.250754 1.0</diffuse>
        <specular>0.2508273 0.2508273 0.2508273 1.0</specular>
        <emissive>0.0 0.0 0.0 0.0</emissive>
      </material>
    </visual>
    <sensor name="robot_front_3d_laser_sensor" type="ray">
      <pose>0 0 0 0 0 0.0</pose>
      <visualize>false</visualize>
      <update_rate>15</update_rate>
      <ray>
        <scan>
          <horizontal>
            <!-- for a high quality simulation -->
            <samples>1200</samples>
            <min_angle>-3.14159265359</min_angle>
            <max_angle>3.14159265359</max_angle>
          </horizontal>
          <vertical>
            <samples>32</samples>
            <min_angle>-0.0872664625997</min_angle>
            <!-- bpearl has 90 degrees of vertical field of view-->
            <max_angle> 1.4835298642</max_angle>
          </vertical>
        </scan>
        <range>
          <min>0.1</min>
          <max>90</max>
          <resolution>0.01</resolution>
        </range>
        <noise>
          <type>none</type>
        </noise>
      </ray>
      <plugin filename="libgazebo_ros_velodyne_laser.so" name="robot_front_3d_laser_controller">
        <topicName>front_3d_laser/points</topicName>
        <frameName>/robot_front_3d_laser_link</frameName>
        <gaussianNoise>0.008</gaussianNoise>
      </plugin>
    </sensor>
  </gazebo>
  <!-- ANTENNA GPS -->
  <joint name="robot_gps_base_joint" type="fixed">
    <axis xyz="0 1 0"/>
    <origin rpy="0 0 0" xyz="-0.472 0.4 0.456"/>
    <parent link="robot_chassis_link"/>
    <child link="robot_gps_base_link"/>
  </joint>
  <link name="robot_gps_base_link">
    <inertial>
      <origin rpy="0 0 0" xyz="0.0 0 0.015"/>
      <mass value="0.2"/>
      <inertia ixx="0.00012435" ixy="0" ixz="0" iyy="0.00012435" iyz="0" izz="0.0002187"/>
    </inertial>
    <visual>
      <origin rpy="0 0 0" xyz="0 0 0"/>
      <material name="ublox_gps_color">
        <color rgba="0.5 0.5 0.5 1"/>
      </material>
      <geometry>
        <mesh filename="package://robotnik_sensors/meshes/antenna_ANN_MB_mast.stl" scale="1.0 1.0 1.0"/>
      </geometry>
    </visual>
    <collision>
      <origin rpy="0 0 0" xyz="0 0 0"/>
      <geometry>
        <mesh filename="package://robotnik_sensors/meshes/antenna_ANN_MB_mast.stl" scale="1.0 1.0 1.0"/>
      </geometry>
    </collision>
  </link>
  <joint name="robot_gps_joint" type="fixed">
    <axis xyz="1 0 0"/>
    <origin xyz="0.0 0.0 0.01125"/>
    <parent link="robot_gps_base_link"/>
    <child link="robot_gps_link"/>
  </joint>
  <link name="robot_gps_link">
	  </link>
  <gazebo reference="robot_gps_base_link">
    <material>Gazebo/Grey</material>
    <gravity>true</gravity>
  </gazebo>
  <gazebo>
    <plugin filename="libhector_gazebo_ros_gps.so" name="robot_gps_controller">
      <alwaysOn>1</alwaysOn>
      <updateRate>5</updateRate>
      <bodyName>robot_gps_link</bodyName>
      <frameId>robot_gps_link</frameId>
      <topicName>gps/fix</topicName>
      <!-- GPS coordinates -->
      <referenceLatitude>39.5080331</referenceLatitude>
      <referenceLongitude>-0.4619816</referenceLongitude>
      <!-- To set heading in ENU orientation (degrees) -->
      <referenceHeading>90</referenceHeading>
      <velocityTopicName>gps/fix_velocity</velocityTopicName>
      <drift>0.0 0.0 0.0</drift>
      <!--<drift>0.0001 0.0001 0.0001</drift>-->
      <!--<drift>0.3 0.3 0.3</drift>-->
      <gaussianNoise>0.00001 0.00001 0.00001</gaussianNoise>
      <!--<gaussianNoise>0.00001 0.00001 0.00001</gaussianNoise>-->
      <velocityDrift>0.00001 0.00001 0.00001</velocityDrift>
      <!--<velocityGaussianNoise>0.1 0.1 0.1</velocityGaussianNoise>-->
      <velocityGaussianNoise>0.00001 0.00001 0.00001</velocityGaussianNoise>
    </plugin>
  </gazebo>
</robot>

